Workbook

Sheet log_last_100_comparison
B1: > | C1: /scratch/sutan101/test_pgb_for_lue_development_no_window_zonal/lue/log/setup_30min_on_velocity_for_lue.ini_2025-03-06T11.55.42.217080.log | D1: <
A2: 45722 | B2: 12:59:10,429 | C2: virtualOS | D2: DEBUG | E2: Writing | F2: a | G2: pcraster | H2: map | I2: to | J2: : | K2: /scratch/sutan101/test_pgb_for_lue_development_no_window_zonal/lue/states/topWaterLayer_forest_2000-12-31.map
A3: 45722 | B3: 12:59:10,438 | C3: virtualOS | D3: DEBUG | E3: Writing | F3: a | G3: pcraster | H3: map | I3: to | J3: : | K3: /scratch/sutan101/test_pgb_for_lue_development_no_window_zonal/lue/states/storUpp_forest_2000-12-31.map
A4: 45722 | B4: 12:59:10,447 | C4: virtualOS | D4: DEBUG | E4: Writing | F4: a | G4: pcraster | H4: map | I4: to | J4: : | K4: /scratch/sutan101/test_pgb_for_lue_development_no_window_zonal/lue/states/storLow_forest_2000-12-31.map
A5: 45722 | B5: 12:59:10,456 | C5: virtualOS | D5: DEBUG | E5: Writing | F5: a | G5: pcraster | H5: map | I5: to | J5: : | K5: /scratch/sutan101/test_pgb_for_lue_development_no_window_zonal/lue/states/interflow_forest_2000-12-31.map
A6: 45722 | B6: 12:59:10,464 | C6: virtualOS | D6: DEBUG | E6: Writing | F6: a | G6: pcraster | H6: map | I6: to | J6: : | K6: /scratch/sutan101/test_pgb_for_lue_development_no_window_zonal/lue/states/interceptStor_grassland_2000-12-31.map
A7: 45722 | B7: 12:59:10,472 | C7: virtualOS | D7: DEBUG | E7: Writing | F7: a | G7: pcraster | H7: map | I7: to | J7: : | K7: /scratch/sutan101/test_pgb_for_lue_development_no_window_zonal/lue/states/snowCoverSWE_grassland_2000-12-31.map
A8: 45722 | B8: 12:59:10,480 | C8: virtualOS | D8: DEBUG | E8: Writing | F8: a | G8: pcraster | H8: map | I8: to | J8: : | K8: /scratch/sutan101/test_pgb_for_lue_development_no_window_zonal/lue/states/snowFreeWater_grassland_2000-12-31.map
A9: 45722 | B9: 12:59:10,490 | C9: virtualOS | D9: DEBUG | E9: Writing | F9: a | G9: pcraster | H9: map | I9: to | J9: : | K9: /scratch/sutan101/test_pgb_for_lue_development_no_window_zonal/lue/states/topWaterLayer_grassland_2000-12-31.map
A10: 45722 | B10: 12:59:10,499 | C10: virtualOS | D10: DEBUG | E10: Writing | F10: a | G10: pcraster | H10: map | I10: to | J10: : | K10: /scratch/sutan101/test_pgb_for_lue_development_no_window_zonal/lue/states/storUpp_grassland_2000-12-31.map
A11: 45722 | B11: 12:59:10,509 | C11: virtualOS | D11: DEBUG | E11: Writing | F11: a | G11: pcraster | H11: map | I11: to | J11: : | K11: /scratch/sutan101/test_pgb_for_lue_development_no_window_zonal/lue/states/storLow_grassland_2000-12-31.map
A12: 45722 | B12: 12:59:10,517 | C12: virtualOS | D12: DEBUG | E12: Writing | F12: a | G12: pcraster | H12: map | I12: to | J12: : | K12: /scratch/sutan101/test_pgb_for_lue_development_no_window_zonal/lue/states/interflow_grassland_2000-12-31.map
A13: 45722 | B13: 12:59:10,525 | C13: virtualOS | D13: DEBUG | E13: Writing | F13: a | G13: pcraster | H13: map | I13: to | J13: : | K13: /scratch/sutan101/test_pgb_for_lue_development_no_window_zonal/lue/states/storGroundwater_2000-12-31.map
... A34: 45722 | B34: 12:59:10,707 | C34: virtualOS | D34: DEBUG | E34: Writing | F34: a | G34: pcraster | H34: map | I34: to | J34: : | K34: /scratch/sutan101/test_pgb_for_lue_development_no_window_zonal/lue/states/subDischarge_2000-12-31.map
A35: 45722 | B35: 12:59:10,736 | C35: pcrglobwb | D35: INFO
A36: 45722 | B36: 12:59:10,736 | C36: pcrglobwb | D36: INFO | E36: The | F36: following | G36: summary | H36: values | I36: do | J36: not | K36: include | L36: storages | M36: in | N36: surface | O36: water | P36: bodies | Q36: (lake, | R36: reservoir | S36: and | T36: channel | U36: storages).
A37: 45722 | B37: 12:59:10,762 | C37: pcrglobwb | D37: INFO | E37: Total | F37: area | G37: 135104900 | H37: km2
A38: 45722 | B38: 12:59:10,766 | C38: pcrglobwb | D38: INFO | E38: Delta | F38: total | G38: storage | H38: days | I38: 1 | J38: to | K38: 366 | L38: in | M38: 2000 | N38: 1345.408 | O38: km3 | P38: 9.958244 | Q38: mm
A39: 45722 | B39: 12:59:10,769 | C39: pcrglobwb | D39: INFO | E39: Accumulated | F39: precipitation | G39: days | H39: 1 | I39: to | J39: 366 | K39: in | L39: 2000 | M39: 111706.5 | N39: km3 | O39: 826.8128 | P39: mm
A40: 45722 | B40: 12:59:10,771 | C40: pcrglobwb | D40: INFO | E40: Accumulated | F40: baseflow | G40: days | H40: 1 | I40: to | J40: 366 | K40: in | L40: 2000 | M40: 28659.57 | N40: km3 | O40: 212.1283 | P40: mm
A41: 45722 | B41: 12:59:10,772 | C41: pcrglobwb | D41: INFO | E41: Accumulated | F41: surfaceWaterInf | G41: days | H41: 1 | I41: to | J41: 366 | K41: in | L41: 2000 | M41: 0.5590971 | N41: km3 | O41: 0.004138244 | P41: mm
A42: 45722 | B42: 12:59:10,773 | C42: pcrglobwb | D42: INFO | E42: Accumulated | F42: runoff | G42: days | H42: 1 | I42: to | J42: 366 | K42: in | L42: 2000 | M42: 48954.33 | N42: km3 | O42: 362.343 | P42: mm
A43: 45722 | B43: 12:59:10,774 | C43: pcrglobwb | D43: INFO | E43: Accumulated | F43: unmetDemand | G43: days | H43: 1 | I43: to | J43: 366 | K43: in | L43: 2000 | M43: 0 | N43: km3 | O43: 0 | P43: mm
A44: 45722 | B44: 12:59:10,775 | C44: pcrglobwb | D44: INFO | E44: Accumulated | F44: infiltration | G44: days | H44: 1 | I44: to | J44: 366 | K44: in | L44: 2000 | M44: 88584.37 | N44: km3 | O44: 655.6709 | P44: mm
A45: 45722 | B45: 12:59:10,776 | C45: pcrglobwb | D45: INFO | E45: Accumulated | F45: gwRecharge | G45: days | H45: 1 | I45: to | J45: 366 | K45: in | L45: 2000 | M45: 28714.65 | N45: km3 | O45: 212.536 | P45: mm
A46: 45722 | B46: 12:59:10,777 | C46: pcrglobwb | D46: INFO | E46: Accumulated | F46: netLqWaterToSoil | G46: days | H46: 1 | I46: to | J46: 366 | K46: in | L46: 2000 | M46: 99930.74 | N46: km3 | O46: 739.6528 | P46: mm
A47: 45722 | B47: 12:59:10,778 | C47: pcrglobwb | D47: INFO | E47: Accumulated | F47: totalPotET | G47: days | H47: 1 | I47: to | J47: 366 | K47: in | L47: 2000 | M47: 120845.7 | N47: km3 | O47: 894.4584 | P47: mm
A48: 45722 | B48: 12:59:10,779 | C48: pcrglobwb | D48: INFO | E48: Accumulated | F48: actualET | G48: days | H48: 1 | I48: to | J48: 366 | K48: in | L48: 2000 | M48: 61398.3 | N48: km3 | O48: 454.449 | P48: mm
A49: 45722 | B49: 12:59:10,780 | C49: pcrglobwb | D49: INFO | E49: Accumulated | F49: interceptEvap | G49: days | H49: 1 | I49: to | J49: 366 | K49: in | L49: 2000 | M49: 10465.68 | N49: km3 | O49: 77.46336 | P49: mm
A50: 45722 | B50: 12:59:10,781 | C50: pcrglobwb | D50: INFO | E50: Accumulated | F50: openWaterEvap | G50: days | H50: 1 | I50: to | J50: 366 | K50: in | L50: 2000 | M50: 0 | N50: km3 | O50: 0 | P50: mm
... A93: 45722 | B93: 12:59:10,823 | C93: pcrglobwb | D93: INFO | E93: Accumulated | F93: nonIrrigationWaterUse | G93: days | H93: 1 | I93: to | J93: 366 | K93: in | L93: 2000 | M93: 0 | N93: km3 | O93: 0 | P93: mm
A94: 45722 | B94: 12:59:10,823 | C94: pcrglobwb | D94: INFO
A95: 45722 | B95: 12:59:10,823 | C95: pcrglobwb | D95: INFO | E95: The | F95: following | G95: summary | H95: is | I95: for | J95: surface | K95: water | L95: bodies.
A96: 45722 | B96: 12:59:10,825 | C96: pcrglobwb | D96: INFO | E96: Delta | F96: surface | G96: water | H96: storage | I96: days | J96: 1 | K96: to | L96: 366 | M96: in | N96: 2000 | O96: -3795.506 | P96: km3 | Q96: -28.09303 | R96: mm
A97: 45722 | B97: 12:59:10,826 | C97: pcrglobwb | D97: INFO | E97: Accumulated | F97: waterBodyEvaporation | G97: days | H97: 1 | I97: to | J97: 366 | K97: in | L97: 2000 | M97: 26.26398 | N97: km3 | O97: 0.1943969 | P97: mm
A98: 45722 | B98: 12:59:10,827 | C98: pcrglobwb | D98: INFO | E98: Accumulated | F98: surfaceWaterInput | G98: days | H98: 1 | I98: to | J98: 366 | K98: in | L98: 2000 | M98: 48928.32 | N98: km3 | O98: 362.1505 | P98: mm
A99: 45722 | B99: 12:59:10,827 | C99: pcrglobwb | D99: INFO | E99: Accumulated | F99: dischargeAtPitTotal | G99: days | H99: 1 | I99: to | J99: 366 | K99: in | L99: 2000 | M99: 52723.52 | N99: km3 | O99: 390.2413 | P99: mm
A100: 45722 | B100: 12:59:10,828 | C100: pcrglobwb | D100: INFO | E100: Accumulated | F100: surfaceWaterBalance | G100: days | H100: 1 | I100: to | J100: 366 | K100: in | L100: 2000 | M100: -0.3114271 | N100: km3 | O100: -0.002305076 | P100: mm
A101: 45722 | B101: 12:59:10,835 | C101: reporting | D101: INFO | E101: reporting | F101: for | G101: time | H101: 36891
B103: > | C103: /scratch/sutan101/test_pgb_for_lue_development_no_window_zonal/pcraster/log/setup_30min_on_velocity_for_lue.ini_2025-03-05T00.55.26.658298.log | D103: <
...

Sheet comparison
A1: variables | B1: lue | C1: pcraster | D1: diff = lue - pcraster | E1: diff / pcraster (%)
A2: =log_last_100_comparison!F39 -> precipitation | B2: =log_last_100_comparison!M39 -> 111706.5 | C2: =log_last_100_comparison!M141 -> 111706 | D2: =B2-C2 -> 0.5 | E2: =IF(D2>0,D2/C2,0) -> 4.4760353e-06
A3: =log_last_100_comparison!F40 -> baseflow | B3: =log_last_100_comparison!M40 -> 28659.57 | C3: =log_last_100_comparison!M142 -> 28659.81 | D3: =B3-C3 -> -0.24 | E3: =IF(D3>0,D3/C3,0) -> 0
A4: =log_last_100_comparison!F41 -> surfaceWaterInf | B4: =log_last_100_comparison!M41 -> 0.5590971 | C4: =log_last_100_comparison!M143 -> 0.5590975 | D4: =B4-C4 -> -4e-07 | E4: =IF(D4>0,D4/C4,0) -> 0
A5: =log_last_100_comparison!F42 -> runoff | B5: =log_last_100_comparison!M42 -> 48954.33 | C5: =log_last_100_comparison!M144 -> 48954.41 | D5: =B5-C5 -> -0.08 | E5: =IF(D5>0,D5/C5,0) -> 0
A6: =log_last_100_comparison!F43 -> unmetDemand | B6: =log_last_100_comparison!M43 -> 0 | C6: =log_last_100_comparison!M145 -> 0 | D6: =B6-C6 -> 0 | E6: =IF(D6>0,D6/C6,0) -> 0
A7: =log_last_100_comparison!F44 -> infiltration | B7: =log_last_100_comparison!M44 -> 88584.37 | C7: =log_last_100_comparison!M146 -> 88584.22 | D7: =B7-C7 -> 0.15 | E7: =IF(D7>0,D7/C7,0) -> 1.6933038e-06
A8: =log_last_100_comparison!F45 -> gwRecharge | B8: =log_last_100_comparison!M45 -> 28714.65 | C8: =log_last_100_comparison!M147 -> 28714.7 | D8: =B8-C8 -> -0.05 | E8: =IF(D8>0,D8/C8,0) -> 0
A9: =log_last_100_comparison!F46 -> netLqWaterToSoil | B9: =log_last_100_comparison!M46 -> 99930.74 | C9: =log_last_100_comparison!M148 -> 99930.31 | D9: =B9-C9 -> 0.43 | E9: =IF(D9>0,D9/C9,0) -> 4.3029988e-06
A10: =log_last_100_comparison!F47 -> totalPotET | B10: =log_last_100_comparison!M47 -> 120845.7 | C10: =log_last_100_comparison!M149 -> 120846.2 | D10: =B10-C10 -> -0.5 | E10: =IF(D10>0,D10/C10,0) -> 0
A11: =log_last_100_comparison!F48 -> actualET | B11: =log_last_100_comparison!M48 -> 61398.3 | C11: =log_last_100_comparison!M150 -> 61398.22 | D11: =B11-C11 -> 0.08 | E11: =IF(D11>0,D11/C11,0) -> 1.3029694e-06
A12: =log_last_100_comparison!F49 -> interceptEvap | B12: =log_last_100_comparison!M49 -> 10465.68 | C12: =log_last_100_comparison!M151 -> 10465.68 | D12: =B12-C12 -> 0 | E12: =IF(D12>0,D12/C12,0) -> 0
A13: =log_last_100_comparison!F50 -> openWaterEvap | B13: =log_last_100_comparison!M50 -> 0 | C13: =log_last_100_comparison!M152 -> 0 | D13: =B13-C13 -> 0 | E13: =IF(D13>0,D13/C13,0) -> 0
... A56: =log_last_100_comparison!F93 -> nonIrrigationWaterUse | B56: =log_last_100_comparison!M93 -> 0 | C56: =log_last_100_comparison!M195 -> 0 | D56: =B56-C56 -> 0 | E56: =IF(D56>0,D56/C56,0) -> 0
A57: =log_last_100_comparison!F97 -> waterBodyEvaporation | B57: =log_last_100_comparison!M97 -> 26.26398 | C57: =log_last_100_comparison!M199 -> 33.27141 | D57: =B57-C57 -> -7.00743 | E57: =IF(D57>0,D57/C57,0) -> 0
A58: =log_last_100_comparison!F98 -> surfaceWaterInput | B58: =log_last_100_comparison!M98 -> 48928.32 | C58: =log_last_100_comparison!M200 -> 48921.14 | D58: =B58-C58 -> 7.18 | E58: =IF(D58>0,D58/C58,0) -> 0.00014676682
A59: =log_last_100_comparison!F99 -> dischargeAtPitTotal | B59: =log_last_100_comparison!M99 -> 52723.52 | C59: =log_last_100_comparison!M201 -> 52746.71 | D59: =B59-C59 -> -23.19 | E59: =IF(D59>0,D59/C59,0) -> 0
A60: =log_last_100_comparison!F100 -> surfaceWaterBalance | B60: =log_last_100_comparison!M100 -> -0.3114271 | C60: =log_last_100_comparison!M202 -> 0.002359296 | D60: =B60-C60 -> -0.3137864 | E60: =IF(D60>0,D60/C60,0) -> 0
